Workbook

Sheet output.csv
A1: Strategy | B1: Turns | C1: TimesSped | D1: Jail | E1: Go | F1: Mediterranean Avenue | G1: Community Chest1 | H1: Baltic Avenue | I1: Income Tax | J1: Reading Railroad | K1: Oriental Avenue | L1: Chance1 | M1: Vermont Avenue | N1: Connecticut Avenue | O1: Just Visiting | P1: St. Charles Place | Q1: Electric Company | R1: States Avenue | S1: Virginia Avenue | T1: Pennsylvania Railroad | U1: St. James Place | V1: Community Chest2 | W1: Tennessee Avenue | X1: New York Avenue | Y1: Free Parking | Z1: Kentucky Avenue | AA1: Chance2 | AB1: Indiana Avenue | AC1: Illinois Avenue | AD1: B. & O. Railroad | AE1: Atlantic Avenue | AF1: Ventnor Avenue | AG1: Water Works | AH1: Marvin Gardens | AI1: Go To Jail | AJ1: Pacific Avenue | AK1: North Carolina Avenue | AL1: Community Chest3 | AM1: Pennsylvania Avenue | AN1: Short Line | AO1: Chance3 | AP1: Park Place | AQ1: Luxury Tax | AR1: Boardwalk
A2: Escapes | B2: 1000 | C2: 50 | D2: 75 | E2: 31 | F2: 16 | G2: 16 | H2: 23 | I2: 20 | J2: 23 | K2: 22 | L2: 5 | M2: 19 | N2: 18 | O2: 21 | P2: 25 | Q2: 17 | R2: 25 | S2: 31 | T2: 22 | U2: 28 | V2: 33 | W2: 28 | X2: 29 | Y2: 31 | Z2: 20 | AA2: 10 | AB2: 28 | AC2: 33 | AD2: 36 | AE2: 19 | AF2: 36 | AG2: 31 | AH2: 20 | AI2: 0 | AJ2: 25 | AK2: 38 | AL2: 21 | AM2: 19 | AN2: 18 | AO2: 15 | AP2: 21 | AQ2: 25 | AR2: 27
A3: Escapes | B3: 1000 | C3: 46 | D3: 80 | E3: 18 | F3: 21 | G3: 17 | H3: 24 | I3: 21 | J3: 29 | K3: 15 | L3: 14 | M3: 23 | N3: 16 | O3: 24 | P3: 25 | Q3: 15 | R3: 22 | S3: 31 | T3: 28 | U3: 28 | V3: 32 | W3: 31 | X3: 38 | Y3: 27 | Z3: 21 | AA3: 8 | AB3: 25 | AC3: 28 | AD3: 29 | AE3: 34 | AF3: 28 | AG3: 27 | AH3: 16 | AI3: 0 | AJ3: 27 | AK3: 31 | AL3: 19 | AM3: 27 | AN3: 25 | AO3: 10 | AP3: 18 | AQ3: 23 | AR3: 25
A4: Escapes | B4: 1000 | C4: 52 | D4: 76 | E4: 28 | F4: 19 | G4: 22 | H4: 16 | I4: 24 | J4: 30 | K4: 18 | L4: 6 | M4: 17 | N4: 15 | O4: 22 | P4: 33 | Q4: 27 | R4: 18 | S4: 21 | T4: 27 | U4: 25 | V4: 33 | W4: 35 | X4: 36 | Y4: 25 | Z4: 27 | AA4: 10 | AB4: 33 | AC4: 31 | AD4: 25 | AE4: 23 | AF4: 34 | AG4: 21 | AH4: 32 | AI4: 0 | AJ4: 26 | AK4: 29 | AL4: 22 | AM4: 25 | AN4: 24 | AO4: 13 | AP4: 16 | AQ4: 16 | AR4: 20
A5: Escapes | B5: 1000 | C5: 51 | D5: 84 | E5: 41 | F5: 14 | G5: 11 | H5: 22 | I5: 20 | J5: 24 | K5: 22 | L5: 9 | M5: 19 | N5: 16 | O5: 18 | P5: 33 | Q5: 20 | R5: 16 | S5: 30 | T5: 29 | U5: 24 | V5: 24 | W5: 42 | X5: 27 | Y5: 32 | Z5: 30 | AA5: 15 | AB5: 23 | AC5: 19 | AD5: 40 | AE5: 34 | AF5: 21 | AG5: 31 | AH5: 19 | AI5: 0 | AJ5: 25 | AK5: 30 | AL5: 23 | AM5: 21 | AN5: 25 | AO5: 7 | AP5: 19 | AQ5: 15 | AR5: 26
A6: Escapes | B6: 1000 | C6: 46 | D6: 70 | E6: 27 | F6: 13 | G6: 16 | H6: 29 | I6: 23 | J6: 27 | K6: 20 | L6: 5 | M6: 21 | N6: 27 | O6: 22 | P6: 18 | Q6: 22 | R6: 27 | S6: 28 | T6: 24 | U6: 34 | V6: 23 | W6: 36 | X6: 33 | Y6: 20 | Z6: 30 | AA6: 16 | AB6: 37 | AC6: 32 | AD6: 33 | AE6: 20 | AF6: 23 | AG6: 29 | AH6: 21 | AI6: 0 | AJ6: 22 | AK6: 27 | AL6: 18 | AM6: 24 | AN6: 22 | AO6: 12 | AP6: 24 | AQ6: 19 | AR6: 26
A7: Escapes | B7: 1000 | C7: 48 | D7: 78 | E7: 31 | F7: 21 | G7: 16 | H7: 23 | I7: 22 | J7: 21 | K7: 23 | L7: 11 | M7: 20 | N7: 19 | O7: 15 | P7: 23 | Q7: 27 | R7: 26 | S7: 25 | T7: 30 | U7: 27 | V7: 24 | W7: 36 | X7: 34 | Y7: 25 | Z7: 26 | AA7: 15 | AB7: 24 | AC7: 36 | AD7: 21 | AE7: 30 | AF7: 27 | AG7: 24 | AH7: 31 | AI7: 0 | AJ7: 20 | AK7: 32 | AL7: 20 | AM7: 28 | AN7: 28 | AO7: 8 | AP7: 11 | AQ7: 14 | AR7: 28
A8: Escapes | B8: 1000 | C8: 49 | D8: 74 | E8: 30 | F8: 16 | G8: 19 | H8: 20 | I8: 23 | J8: 31 | K8: 21 | L8: 9 | M8: 17 | N8: 23 | O8: 23 | P8: 28 | Q8: 18 | R8: 23 | S8: 24 | T8: 22 | U8: 30 | V8: 32 | W8: 24 | X8: 36 | Y8: 28 | Z8: 23 | AA8: 10 | AB8: 27 | AC8: 33 | AD8: 33 | AE8: 18 | AF8: 30 | AG8: 26 | AH8: 26 | AI8: 0 | AJ8: 29 | AK8: 25 | AL8: 20 | AM8: 36 | AN8: 17 | AO8: 7 | AP8: 27 | AQ8: 13 | AR8: 29
A9: Escapes | B9: 1000 | C9: 47 | D9: 73 | E9: 21 | F9: 18 | G9: 10 | H9: 22 | I9: 24 | J9: 27 | K9: 23 | L9: 5 | M9: 21 | N9: 19 | O9: 18 | P9: 27 | Q9: 27 | R9: 23 | S9: 33 | T9: 29 | U9: 28 | V9: 22 | W9: 23 | X9: 39 | Y9: 31 | Z9: 30 | AA9: 13 | AB9: 26 | AC9: 20 | AD9: 31 | AE9: 27 | AF9: 31 | AG9: 31 | AH9: 27 | AI9: 0 | AJ9: 25 | AK9: 31 | AL9: 20 | AM9: 17 | AN9: 21 | AO9: 15 | AP9: 22 | AQ9: 29 | AR9: 21
A10: Escapes | B10: 1000 | C10: 55 | D10: 79 | E10: 25 | F10: 23 | G10: 20 | H10: 26 | I10: 13 | J10: 30 | K10: 17 | L10: 11 | M10: 14 | N10: 17 | O10: 35 | P10: 20 | Q10: 25 | R10: 21 | S10: 23 | T10: 34 | U10: 33 | V10: 24 | W10: 34 | X10: 37 | Y10: 37 | Z10: 17 | AA10: 9 | AB10: 21 | AC10: 23 | AD10: 28 | AE10: 29 | AF10: 30 | AG10: 35 | AH10: 22 | AI10: 0 | AJ10: 19 | AK10: 18 | AL10: 27 | AM10: 24 | AN10: 30 | AO10: 7 | AP10: 22 | AQ10: 20 | AR10: 21
A11: Escapes | B11: 1000 | C11: 50 | D11: 78 | E11: 33 | F11: 9 | G11: 21 | H11: 20 | I11: 21 | J11: 33 | K11: 21 | L11: 10 | M11: 13 | N11: 24 | O11: 18 | P11: 27 | Q11: 26 | R11: 20 | S11: 21 | T11: 28 | U11: 36 | V11: 23 | W11: 35 | X11: 30 | Y11: 29 | Z11: 34 | AA11: 11 | AB11: 19 | AC11: 31 | AD11: 26 | AE11: 37 | AF11: 23 | AG11: 29 | AH11: 25 | AI11: 0 | AJ11: 17 | AK11: 30 | AL11: 20 | AM11: 25 | AN11: 26 | AO11: 8 | AP11: 21 | AQ11: 19 | AR11: 23
A12: Escapes | B12: 10000 | C12: 519 | D12: 820 | E12: 287 | F12: 208 | G12: 169 | H12: 189 | I12: 224 | J12: 242 | K12: 189 | L12: 102 | M12: 185 | N12: 187 | O12: 177 | P12: 273 | Q12: 214 | R12: 234 | S12: 237 | T12: 283 | U12: 296 | V12: 303 | W12: 279 | X12: 341 | Y12: 303 | Z12: 278 | AA12: 130 | AB12: 264 | AC12: 309 | AD12: 317 | AE12: 276 | AF12: 234 | AG12: 257 | AH12: 247 | AI12: 0 | AJ12: 259 | AK12: 267 | AL12: 229 | AM12: 242 | AN12: 231 | AO12: 81 | AP12: 195 | AQ12: 202 | AR12: 240
A13: Escapes | B13: 10000 | C13: 509 | D13: 811 | E13: 280 | F13: 231 | G13: 163 | H13: 175 | I13: 212 | J13: 263 | K13: 197 | L13: 101 | M13: 199 | N13: 189 | O13: 186 | P13: 220 | Q13: 224 | R13: 242 | S13: 243 | T13: 266 | U13: 287 | V13: 275 | W13: 335 | X13: 330 | Y13: 292 | Z13: 285 | AA13: 127 | AB13: 269 | AC13: 309 | AD13: 294 | AE13: 277 | AF13: 272 | AG13: 268 | AH13: 244 | AI13: 0 | AJ13: 260 | AK13: 266 | AL13: 231 | AM13: 252 | AN13: 214 | AO13: 70 | AP13: 194 | AQ13: 213 | AR13: 234
... A81: Waits | B81: 1000000 | C81: 46903 | D81: 157669 | E81: 25941 | F81: 17321 | G81: 15343 | H81: 17333 | I81: 18934 | J81: 24163 | K81: 18063 | L81: 7890 | M81: 18188 | N81: 18058 | O81: 17547 | P81: 21311 | Q81: 23311 | R81: 19432 | S81: 23605 | T81: 25434 | U81: 28004 | V81: 24123 | W81: 29192 | X81: 28228 | Y81: 28649 | Z81: 25737 | AA81: 12065 | AB81: 24320 | AC81: 28882 | AD81: 27861 | AE81: 24438 | AF81: 24220 | AG81: 25598 | AH81: 22963 | AI81: 0 | AJ81: 23256 | AK81: 23146 | AL81: 20444 | AM81: 21585 | AN81: 20732 | AO81: 8597 | AP81: 18016 | AQ81: 18452 | AR81: 21949

Sheet percentages
A1: =output.csv!A1 -> Strategy | B1: =output.csv!B1 -> Turns | C1: =output.csv!C1 -> TimesSped | D1: =output.csv!D1 -> Jail | E1: =output.csv!E1 -> Go | F1: =output.csv!F1 -> Mediterranean Avenue | G1: =output.csv!G1 -> Community Chest1 | H1: =output.csv!H1 -> Baltic Avenue | ... AR1: =output.csv!AR1 -> Boardwalk
A2: =output.csv!A2 -> Escapes | B2: =output.csv!B2 -> 1000 | C2: =output.csv!C2 / output.csv!$B2 -> 0.05 | D2: =output.csv!D2 / output.csv!$B2 -> 0.075 | E2: =output.csv!E2 / output.csv!$B2 -> 0.031 | F2: =output.csv!F2 / output.csv!$B2 -> 0.016 | G2: =output.csv!G2 / output.csv!$B2 -> 0.016 | H2: =output.csv!H2 / output.csv!$B2 -> 0.023 | I2: =output.csv!I2 / output.csv!$B2 -> 0.02 | J2: =output.csv!J2 / output.csv!$B2 -> 0.023 | ... AR2: =output.csv!AR2 / output.csv!$B2 -> 0.027
A3: =output.csv!A3 -> Escapes | B3: =output.csv!B3 -> 1000 | C3: =output.csv!C3 / output.csv!$B3 -> 0.046 | D3: =output.csv!D3 / output.csv!$B3 -> 0.08 | E3: =output.csv!E3 / output.csv!$B3 -> 0.018 | F3: =output.csv!F3 / output.csv!$B3 -> 0.021 | G3: =output.csv!G3 / output.csv!$B3 -> 0.017 | H3: =output.csv!H3 / output.csv!$B3 -> 0.024 | I3: =output.csv!I3 / output.csv!$B3 -> 0.021 | J3: =output.csv!J3 / output.csv!$B3 -> 0.029 | ... AR3: =output.csv!AR3 / output.csv!$B3 -> 0.025
A4: =output.csv!A4 -> Escapes | B4: =output.csv!B4 -> 1000 | C4: =output.csv!C4 / output.csv!$B4 -> 0.052 | D4: =output.csv!D4 / output.csv!$B4 -> 0.076 | E4: =output.csv!E4 / output.csv!$B4 -> 0.028 | F4: =output.csv!F4 / output.csv!$B4 -> 0.019 | G4: =output.csv!G4 / output.csv!$B4 -> 0.022 | H4: =output.csv!H4 / output.csv!$B4 -> 0.016 | I4: =output.csv!I4 / output.csv!$B4 -> 0.024 | J4: =output.csv!J4 / output.csv!$B4 -> 0.03 | ... AR4: =output.csv!AR4 / output.csv!$B4 -> 0.02
A5: =output.csv!A5 -> Escapes | B5: =output.csv!B5 -> 1000 | C5: =output.csv!C5 / output.csv!$B5 -> 0.051 | D5: =output.csv!D5 / output.csv!$B5 -> 0.084 | E5: =output.csv!E5 / output.csv!$B5 -> 0.041 | F5: =output.csv!F5 / output.csv!$B5 -> 0.014 | G5: =output.csv!G5 / output.csv!$B5 -> 0.011 | H5: =output.csv!H5 / output.csv!$B5 -> 0.022 | I5: =output.csv!I5 / output.csv!$B5 -> 0.02 | J5: =output.csv!J5 / output.csv!$B5 -> 0.024 | ... AR5: =output.csv!AR5 / output.csv!$B5 -> 0.026
A6: =output.csv!A6 -> Escapes | B6: =output.csv!B6 -> 1000 | C6: =output.csv!C6 / output.csv!$B6 -> 0.046 | D6: =output.csv!D6 / output.csv!$B6 -> 0.07 | E6: =output.csv!E6 / output.csv!$B6 -> 0.027 | F6: =output.csv!F6 / output.csv!$B6 -> 0.013 | G6: =output.csv!G6 / output.csv!$B6 -> 0.016 | H6: =output.csv!H6 / output.csv!$B6 -> 0.029 | I6: =output.csv!I6 / output.csv!$B6 -> 0.023 | J6: =output.csv!J6 / output.csv!$B6 -> 0.027 | ... AR6: =output.csv!AR6 / output.csv!$B6 -> 0.026
A7: =output.csv!A7 -> Escapes | B7: =output.csv!B7 -> 1000 | C7: =output.csv!C7 / output.csv!$B7 -> 0.048 | D7: =output.csv!D7 / output.csv!$B7 -> 0.078 | E7: =output.csv!E7 / output.csv!$B7 -> 0.031 | F7: =output.csv!F7 / output.csv!$B7 -> 0.021 | G7: =output.csv!G7 / output.csv!$B7 -> 0.016 | H7: =output.csv!H7 / output.csv!$B7 -> 0.023 | I7: =output.csv!I7 / output.csv!$B7 -> 0.022 | J7: =output.csv!J7 / output.csv!$B7 -> 0.021 | ... AR7: =output.csv!AR7 / output.csv!$B7 -> 0.028
A8: =output.csv!A8 -> Escapes | B8: =output.csv!B8 -> 1000 | C8: =output.csv!C8 / output.csv!$B8 -> 0.049 | D8: =output.csv!D8 / output.csv!$B8 -> 0.074 | E8: =output.csv!E8 / output.csv!$B8 -> 0.03 | F8: =output.csv!F8 / output.csv!$B8 -> 0.016 | G8: =output.csv!G8 / output.csv!$B8 -> 0.019 | H8: =output.csv!H8 / output.csv!$B8 -> 0.02 | I8: =output.csv!I8 / output.csv!$B8 -> 0.023 | J8: =output.csv!J8 / output.csv!$B8 -> 0.031 | ... AR8: =output.csv!AR8 / output.csv!$B8 -> 0.029
A9: =output.csv!A9 -> Escapes | B9: =output.csv!B9 -> 1000 | C9: =output.csv!C9 / output.csv!$B9 -> 0.047 | D9: =output.csv!D9 / output.csv!$B9 -> 0.073 | E9: =output.csv!E9 / output.csv!$B9 -> 0.021 | F9: =output.csv!F9 / output.csv!$B9 -> 0.018 | G9: =output.csv!G9 / output.csv!$B9 -> 0.01 | H9: =output.csv!H9 / output.csv!$B9 -> 0.022 | I9: =output.csv!I9 / output.csv!$B9 -> 0.024 | J9: =output.csv!J9 / output.csv!$B9 -> 0.027 | ... AR9: =output.csv!AR9 / output.csv!$B9 -> 0.021
A10: =output.csv!A10 -> Escapes | B10: =output.csv!B10 -> 1000 | C10: =output.csv!C10 / output.csv!$B10 -> 0.055 | D10: =output.csv!D10 / output.csv!$B10 -> 0.079 | E10: =output.csv!E10 / output.csv!$B10 -> 0.025 | F10: =output.csv!F10 / output.csv!$B10 -> 0.023 | G10: =output.csv!G10 / output.csv!$B10 -> 0.02 | H10: =output.csv!H10 / output.csv!$B10 -> 0.026 | I10: =output.csv!I10 / output.csv!$B10 -> 0.013 | J10: =output.csv!J10 / output.csv!$B10 -> 0.03 | ... AR10: =output.csv!AR10 / output.csv!$B10 -> 0.021
A11: =output.csv!A11 -> Escapes | B11: =output.csv!B11 -> 1000 | C11: =output.csv!C11 / output.csv!$B11 -> 0.05 | D11: =output.csv!D11 / output.csv!$B11 -> 0.078 | E11: =output.csv!E11 / output.csv!$B11 -> 0.033 | F11: =output.csv!F11 / output.csv!$B11 -> 0.009 | G11: =output.csv!G11 / output.csv!$B11 -> 0.021 | H11: =output.csv!H11 / output.csv!$B11 -> 0.02 | I11: =output.csv!I11 / output.csv!$B11 -> 0.021 | J11: =output.csv!J11 / output.csv!$B11 -> 0.033 | ... AR11: =output.csv!AR11 / output.csv!$B11 -> 0.023
B12: Average | C12: =AVERAGE(C2:C11) -> 0.0494 | D12: =AVERAGE(D2:D11) -> 0.0767 | E12: =AVERAGE(E2:E11) -> 0.0285 | F12: =AVERAGE(F2:F11) -> 0.017 | G12: =AVERAGE(G2:G11) -> 0.0168 | H12: =AVERAGE(H2:H11) -> 0.0225 | I12: =AVERAGE(I2:I11) -> 0.0211 | J12: =AVERAGE(J2:J11) -> 0.0275 | ... AR12: =AVERAGE(AR2:AR11) -> 0.0246
B13: Standard Deviation | C13: =_xlfn.stdev.s(C2:C11)*100 -> 0.2836273 | D13: =_xlfn.stdev.s(D2:D11)*100 -> 0.39735235 | E13: =_xlfn.stdev.s(E2:E11)*100 -> 0.64334197 | F13: =_xlfn.stdev.s(F2:F11)*100 -> 0.42687495 | G13: =_xlfn.stdev.s(G2:G11)*100 -> 0.39665266 | H13: =_xlfn.stdev.s(H2:H11)*100 -> 0.35355339 | I13: =_xlfn.stdev.s(I2:I11)*100 -> 0.32128215 | J13: =_xlfn.stdev.s(J2:J11)*100 -> 0.38369548 | ... AR13: =_xlfn.stdev.s(AR2:AR11)*100 -> 0.31692972
A14: =output.csv!A12 -> Escapes | B14: =output.csv!B12 -> 10000 | C14: =output.csv!C12 / output.csv!$B12 -> 0.0519 | D14: =output.csv!D12 / output.csv!$B12 -> 0.082 | E14: =output.csv!E12 / output.csv!$B12 -> 0.0287 | F14: =output.csv!F12 / output.csv!$B12 -> 0.0208 | G14: =output.csv!G12 / output.csv!$B12 -> 0.0169 | H14: =output.csv!H12 / output.csv!$B12 -> 0.0189 | I14: =output.csv!I12 / output.csv!$B12 -> 0.0224 | J14: =output.csv!J12 / output.csv!$B12 -> 0.0242 | ... AR14: =output.csv!AR12 / output.csv!$B12 -> 0.024
A15: =output.csv!A13 -> Escapes | B15: =output.csv!B13 -> 10000 | C15: =output.csv!C13 / output.csv!$B13 -> 0.0509 | D15: =output.csv!D13 / output.csv!$B13 -> 0.0811 | E15: =output.csv!E13 / output.csv!$B13 -> 0.028 | F15: =output.csv!F13 / output.csv!$B13 -> 0.0231 | G15: =output.csv!G13 / output.csv!$B13 -> 0.0163 | H15: =output.csv!H13 / output.csv!$B13 -> 0.0175 | I15: =output.csv!I13 / output.csv!$B13 -> 0.0212 | J15: =output.csv!J13 / output.csv!$B13 -> 0.0263 | ... AR15: =output.csv!AR13 / output.csv!$B13 -> 0.0234
A16: =output.csv!A14 -> Escapes | B16: =output.csv!B14 -> 10000 | C16: =output.csv!C14 / output.csv!$B14 -> 0.0502 | D16: =output.csv!D14 / output.csv!$B14 -> 0.0791 | E16: =output.csv!E14 / output.csv!$B14 -> 0.0291 | F16: =output.csv!F14 / output.csv!$B14 -> 0.0185 | G16: =output.csv!G14 / output.csv!$B14 -> 0.0179 | H16: =output.csv!H14 / output.csv!$B14 -> 0.0187 | I16: =output.csv!I14 / output.csv!$B14 -> 0.0223 | J16: =output.csv!J14 / output.csv!$B14 -> 0.0266 | ... AR16: =output.csv!AR14 / output.csv!$B14 -> 0.023
A17: =output.csv!A15 -> Escapes | B17: =output.csv!B15 -> 10000 | C17: =output.csv!C15 / output.csv!$B15 -> 0.0514 | D17: =output.csv!D15 / output.csv!$B15 -> 0.0814 | E17: =output.csv!E15 / output.csv!$B15 -> 0.0296 | F17: =output.csv!F15 / output.csv!$B15 -> 0.0189 | G17: =output.csv!G15 / output.csv!$B15 -> 0.0178 | H17: =output.csv!H15 / output.csv!$B15 -> 0.021 | I17: =output.csv!I15 / output.csv!$B15 -> 0.0217 | J17: =output.csv!J15 / output.csv!$B15 -> 0.0248 | ... AR17: =output.csv!AR15 / output.csv!$B15 -> 0.0214
A18: =output.csv!A16 -> Escapes | B18: =output.csv!B16 -> 10000 | C18: =output.csv!C16 / output.csv!$B16 -> 0.0528 | D18: =output.csv!D16 / output.csv!$B16 -> 0.0851 | E18: =output.csv!E16 / output.csv!$B16 -> 0.0285 | F18: =output.csv!F16 / output.csv!$B16 -> 0.0185 | G18: =output.csv!G16 / output.csv!$B16 -> 0.0177 | H18: =output.csv!H16 / output.csv!$B16 -> 0.0179 | I18: =output.csv!I16 / output.csv!$B16 -> 0.0204 | J18: =output.csv!J16 / output.csv!$B16 -> 0.0262 | ... AR18: =output.csv!AR16 / output.csv!$B16 -> 0.0256
A19: =output.csv!A17 -> Escapes | B19: =output.csv!B17 -> 10000 | C19: =output.csv!C17 / output.csv!$B17 -> 0.0491 | D19: =output.csv!D17 / output.csv!$B17 -> 0.0783 | E19: =output.csv!E17 / output.csv!$B17 -> 0.0283 | F19: =output.csv!F17 / output.csv!$B17 -> 0.0185 | G19: =output.csv!G17 / output.csv!$B17 -> 0.0171 | H19: =output.csv!H17 / output.csv!$B17 -> 0.0218 | I19: =output.csv!I17 / output.csv!$B17 -> 0.0192 | J19: =output.csv!J17 / output.csv!$B17 -> 0.0271 | ... AR19: =output.csv!AR17 / output.csv!$B17 -> 0.0244
A20: =output.csv!A18 -> Escapes | B20: =output.csv!B18 -> 10000 | C20: =output.csv!C18 / output.csv!$B18 -> 0.0495 | D20: =output.csv!D18 / output.csv!$B18 -> 0.0788 | E20: =output.csv!E18 / output.csv!$B18 -> 0.0286 | F20: =output.csv!F18 / output.csv!$B18 -> 0.0174 | G20: =output.csv!G18 / output.csv!$B18 -> 0.0164 | H20: =output.csv!H18 / output.csv!$B18 -> 0.019 | I20: =output.csv!I18 / output.csv!$B18 -> 0.0231 | J20: =output.csv!J18 / output.csv!$B18 -> 0.0248 | ... AR20: =output.csv!AR18 / output.csv!$B18 -> 0.0259
A21: =output.csv!A19 -> Escapes | B21: =output.csv!B19 -> 10000 | C21: =output.csv!C19 / output.csv!$B19 -> 0.0504 | D21: =output.csv!D19 / output.csv!$B19 -> 0.0813 | E21: =output.csv!E19 / output.csv!$B19 -> 0.0297 | F21: =output.csv!F19 / output.csv!$B19 -> 0.0174 | G21: =output.csv!G19 / output.csv!$B19 -> 0.0193 | H21: =output.csv!H19 / output.csv!$B19 -> 0.0184 | I21: =output.csv!I19 / output.csv!$B19 -> 0.0202 | J21: =output.csv!J19 / output.csv!$B19 -> 0.0256 | ... AR21: =output.csv!AR19 / output.csv!$B19 -> 0.0232
A22: =output.csv!A20 -> Escapes | B22: =output.csv!B20 -> 10000 | C22: =output.csv!C20 / output.csv!$B20 -> 0.052 | D22: =output.csv!D20 / output.csv!$B20 -> 0.0834 | E22: =output.csv!E20 / output.csv!$B20 -> 0.027 | F22: =output.csv!F20 / output.csv!$B20 -> 0.0175 | G22: =output.csv!G20 / output.csv!$B20 -> 0.0167 | H22: =output.csv!H20 / output.csv!$B20 -> 0.0199 | I22: =output.csv!I20 / output.csv!$B20 -> 0.0192 | J22: =output.csv!J20 / output.csv!$B20 -> 0.0285 | ... AR22: =output.csv!AR20 / output.csv!$B20 -> 0.0236
A23: =output.csv!A21 -> Escapes | B23: =output.csv!B21 -> 10000 | C23: =output.csv!C21 / output.csv!$B21 -> 0.0515 | D23: =output.csv!D21 / output.csv!$B21 -> 0.083 | E23: =output.csv!E21 / output.csv!$B21 -> 0.0283 | F23: =output.csv!F21 / output.csv!$B21 -> 0.0182 | G23: =output.csv!G21 / output.csv!$B21 -> 0.0166 | H23: =output.csv!H21 / output.csv!$B21 -> 0.018 | I23: =output.csv!I21 / output.csv!$B21 -> 0.023 | J23: =output.csv!J21 / output.csv!$B21 -> 0.0272 | ... AR23: =output.csv!AR21 / output.csv!$B21 -> 0.0245
B24: Average | C24: =AVERAGE(C14:C23) -> 0.05097 | D24: =AVERAGE(D14:D23) -> 0.08135 | E24: =AVERAGE(E14:E23) -> 0.02858 | F24: =AVERAGE(F14:F23) -> 0.01888 | G24: =AVERAGE(G14:G23) -> 0.01727 | H24: =AVERAGE(H14:H23) -> 0.01911 | I24: =AVERAGE(I14:I23) -> 0.02127 | J24: =AVERAGE(J14:J23) -> 0.02613 | ... AR24: =AVERAGE(AR14:AR23) -> 0.0239
B25: Standard Deviation | C25: =_xlfn.stdev.s(C14:C23)*100 -> 0.11700427 | D25: =_xlfn.stdev.s(D14:D23)*100 -> 0.21691012 | E25: =_xlfn.stdev.s(E14:E23)*100 -> 0.078711851 | F25: =_xlfn.stdev.s(F14:F23)*100 -> 0.17849992 | G25: =_xlfn.stdev.s(G14:G23)*100 -> 0.092020529 | H25: =_xlfn.stdev.s(H14:H23)*100 -> 0.13924 | I25: =_xlfn.stdev.s(I14:I23)*100 -> 0.14659468 | J25: =_xlfn.stdev.s(J14:J23)*100 -> 0.1312377 | ... AR25: =_xlfn.stdev.s(AR14:AR23)*100 -> 0.13080945
A26: =output.csv!A22 -> Escapes | B26: =output.csv!B22 -> 100000 | C26: =output.csv!C22 / output.csv!$B22 -> 0.05105 | D26: =output.csv!D22 / output.csv!$B22 -> 0.08145 | E26: =output.csv!E22 / output.csv!$B22 -> 0.02893 | F26: =output.csv!F22 / output.csv!$B22 -> 0.01892 | G26: =output.csv!G22 / output.csv!$B22 -> 0.01653 | H26: =output.csv!H22 / output.csv!$B22 -> 0.01858 | I26: =output.csv!I22 / output.csv!$B22 -> 0.02047 | J26: =output.csv!J22 / output.csv!$B22 -> 0.02612 | ... AR26: =output.csv!AR22 / output.csv!$B22 -> 0.0237
A27: =output.csv!A23 -> Escapes | B27: =output.csv!B23 -> 100000 | C27: =output.csv!C23 / output.csv!$B23 -> 0.05137 | D27: =output.csv!D23 / output.csv!$B23 -> 0.08172 | E27: =output.csv!E23 / output.csv!$B23 -> 0.02891 | F27: =output.csv!F23 / output.csv!$B23 -> 0.01872 | G27: =output.csv!G23 / output.csv!$B23 -> 0.01609 | H27: =output.csv!H23 / output.csv!$B23 -> 0.01874 | I27: =output.csv!I23 / output.csv!$B23 -> 0.02106 | J27: =output.csv!J23 / output.csv!$B23 -> 0.02558 | ... AR27: =output.csv!AR23 / output.csv!$B23 -> 0.02376
A28: =output.csv!A24 -> Escapes | B28: =output.csv!B24 -> 100000 | C28: =output.csv!C24 / output.csv!$B24 -> 0.05103 | D28: =output.csv!D24 / output.csv!$B24 -> 0.08044 | E28: =output.csv!E24 / output.csv!$B24 -> 0.02881 | F28: =output.csv!F24 / output.csv!$B24 -> 0.01928 | G28: =output.csv!G24 / output.csv!$B24 -> 0.01648 | H28: =output.csv!H24 / output.csv!$B24 -> 0.01939 | I28: =output.csv!I24 / output.csv!$B24 -> 0.02021 | J28: =output.csv!J24 / output.csv!$B24 -> 0.02612 | ... AR28: =output.csv!AR24 / output.csv!$B24 -> 0.02387
A29: =output.csv!A25 -> Escapes | B29: =output.csv!B25 -> 100000 | C29: =output.csv!C25 / output.csv!$B25 -> 0.05056 | D29: =output.csv!D25 / output.csv!$B25 -> 0.08071 | E29: =output.csv!E25 / output.csv!$B25 -> 0.02888 | F29: =output.csv!F25 / output.csv!$B25 -> 0.01947 | G29: =output.csv!G25 / output.csv!$B25 -> 0.01752 | H29: =output.csv!H25 / output.csv!$B25 -> 0.01913 | I29: =output.csv!I25 / output.csv!$B25 -> 0.02026 | J29: =output.csv!J25 / output.csv!$B25 -> 0.02637 | ... AR29: =output.csv!AR25 / output.csv!$B25 -> 0.0237
A30: =output.csv!A26 -> Escapes | B30: =output.csv!B26 -> 100000 | C30: =output.csv!C26 / output.csv!$B26 -> 0.0509 | D30: =output.csv!D26 / output.csv!$B26 -> 0.08177 | E30: =output.csv!E26 / output.csv!$B26 -> 0.02829 | F30: =output.csv!F26 / output.csv!$B26 -> 0.01977 | G30: =output.csv!G26 / output.csv!$B26 -> 0.01665 | H30: =output.csv!H26 / output.csv!$B26 -> 0.0194 | I30: =output.csv!I26 / output.csv!$B26 -> 0.02052 | J30: =output.csv!J26 / output.csv!$B26 -> 0.02576 | ... AR30: =output.csv!AR26 / output.csv!$B26 -> 0.02353
A31: =output.csv!A27 -> Escapes | B31: =output.csv!B27 -> 100000 | C31: =output.csv!C27 / output.csv!$B27 -> 0.05163 | D31: =output.csv!D27 / output.csv!$B27 -> 0.0811 | E31: =output.csv!E27 / output.csv!$B27 -> 0.02856 | F31: =output.csv!F27 / output.csv!$B27 -> 0.01926 | G31: =output.csv!G27 / output.csv!$B27 -> 0.01652 | H31: =output.csv!H27 / output.csv!$B27 -> 0.01906 | I31: =output.csv!I27 / output.csv!$B27 -> 0.02098 | J31: =output.csv!J27 / output.csv!$B27 -> 0.02625 | ... AR31: =output.csv!AR27 / output.csv!$B27 -> 0.02346
A32: =output.csv!A28 -> Escapes | B32: =output.csv!B28 -> 100000 | C32: =output.csv!C28 / output.csv!$B28 -> 0.05056 | D32: =output.csv!D28 / output.csv!$B28 -> 0.08192 | E32: =output.csv!E28 / output.csv!$B28 -> 0.02826 | F32: =output.csv!F28 / output.csv!$B28 -> 0.01925 | G32: =output.csv!G28 / output.csv!$B28 -> 0.01672 | H32: =output.csv!H28 / output.csv!$B28 -> 0.01927 | I32: =output.csv!I28 / output.csv!$B28 -> 0.02096 | J32: =output.csv!J28 / output.csv!$B28 -> 0.02616 | ... AR32: =output.csv!AR28 / output.csv!$B28 -> 0.02326
A33: =output.csv!A29 -> Escapes | B33: =output.csv!B29 -> 100000 | C33: =output.csv!C29 / output.csv!$B29 -> 0.05076 | D33: =output.csv!D29 / output.csv!$B29 -> 0.08002 | E33: =output.csv!E29 / output.csv!$B29 -> 0.02854 | F33: =output.csv!F29 / output.csv!$B29 -> 0.01912 | G33: =output.csv!G29 / output.csv!$B29 -> 0.01665 | H33: =output.csv!H29 / output.csv!$B29 -> 0.0194 | I33: =output.csv!I29 / output.csv!$B29 -> 0.02045 | J33: =output.csv!J29 / output.csv!$B29 -> 0.0266 | ... AR33: =output.csv!AR29 / output.csv!$B29 -> 0.02416
A34: =output.csv!A30 -> Escapes | B34: =output.csv!B30 -> 100000 | C34: =output.csv!C30 / output.csv!$B30 -> 0.05118 | D34: =output.csv!D30 / output.csv!$B30 -> 0.08077 | E34: =output.csv!E30 / output.csv!$B30 -> 0.02862 | F34: =output.csv!F30 / output.csv!$B30 -> 0.01891 | G34: =output.csv!G30 / output.csv!$B30 -> 0.01751 | H34: =output.csv!H30 / output.csv!$B30 -> 0.01793 | I34: =output.csv!I30 / output.csv!$B30 -> 0.02028 | J34: =output.csv!J30 / output.csv!$B30 -> 0.02571 | ... AR34: =output.csv!AR30 / output.csv!$B30 -> 0.0246
A35: =output.csv!A31 -> Escapes | B35: =output.csv!B31 -> 100000 | C35: =output.csv!C31 / output.csv!$B31 -> 0.05038 | D35: =output.csv!D31 / output.csv!$B31 -> 0.08097 | E35: =output.csv!E31 / output.csv!$B31 -> 0.02879 | F35: =output.csv!F31 / output.csv!$B31 -> 0.01895 | G35: =output.csv!G31 / output.csv!$B31 -> 0.01669 | H35: =output.csv!H31 / output.csv!$B31 -> 0.01935 | I35: =output.csv!I31 / output.csv!$B31 -> 0.02018 | J35: =output.csv!J31 / output.csv!$B31 -> 0.02667 | ... AR35: =output.csv!AR31 / output.csv!$B31 -> 0.02363
B36: Average | C36: =AVERAGE(C26:C35) -> 0.050942 | D36: =AVERAGE(D26:D35) -> 0.081087 | E36: =AVERAGE(E26:E35) -> 0.028659 | F36: =AVERAGE(F26:F35) -> 0.019165 | G36: =AVERAGE(G26:G35) -> 0.016736 | H36: =AVERAGE(H26:H35) -> 0.019025 | I36: =AVERAGE(I26:I35) -> 0.020537 | J36: =AVERAGE(J26:J35) -> 0.026134 | ... AR36: =AVERAGE(AR26:AR35) -> 0.023767
B37: Standard Deviation | C37: =_xlfn.stdev.s(C26:C35)*100 -> 0.039089072 | D37: =_xlfn.stdev.s(D26:D35)*100 -> 0.062418035 | E37: =_xlfn.stdev.s(E26:E35)*100 -> 0.024632634 | F37: =_xlfn.stdev.s(F26:F35)*100 -> 0.030909366 | G37: =_xlfn.stdev.s(G26:G35)*100 -> 0.044756626 | H37: =_xlfn.stdev.s(H26:H35)*100 -> 0.047965844 | I37: =_xlfn.stdev.s(I26:I35)*100 -> 0.033964197 | J37: =_xlfn.stdev.s(J26:J35)*100 -> 0.036533698 | ... AR37: =_xlfn.stdev.s(AR26:AR35)*100 -> 0.037921117
A38: =output.csv!A32 -> Escapes | B38: =output.csv!B32 -> 1000000 | C38: =output.csv!C32 / output.csv!$B32 -> 0.051021 | D38: =output.csv!D32 / output.csv!$B32 -> 0.081342 | E38: =output.csv!E32 / output.csv!$B32 -> 0.028481 | F38: =output.csv!F32 / output.csv!$B32 -> 0.018942 | G38: =output.csv!G32 / output.csv!$B32 -> 0.016881 | H38: =output.csv!H32 / output.csv!$B32 -> 0.019111 | I38: =output.csv!I32 / output.csv!$B32 -> 0.020518 | J38: =output.csv!J32 / output.csv!$B32 -> 0.026077 | ... AR38: =output.csv!AR32 / output.csv!$B32 -> 0.023813
A39: =output.csv!A33 -> Escapes | B39: =output.csv!B33 -> 1000000 | C39: =output.csv!C33 / output.csv!$B33 -> 0.05122 | D39: =output.csv!D33 / output.csv!$B33 -> 0.081432 | E39: =output.csv!E33 / output.csv!$B33 -> 0.028751 | F39: =output.csv!F33 / output.csv!$B33 -> 0.019005 | G39: =output.csv!G33 / output.csv!$B33 -> 0.016658 | H39: =output.csv!H33 / output.csv!$B33 -> 0.019347 | I39: =output.csv!I33 / output.csv!$B33 -> 0.020365 | J39: =output.csv!J33 / output.csv!$B33 -> 0.026198 | ... AR39: =output.csv!AR33 / output.csv!$B33 -> 0.023729
A40: =output.csv!A34 -> Escapes | B40: =output.csv!B34 -> 1000000 | C40: =output.csv!C34 / output.csv!$B34 -> 0.051037 | D40: =output.csv!D34 / output.csv!$B34 -> 0.081551 | E40: =output.csv!E34 / output.csv!$B34 -> 0.02864 | F40: =output.csv!F34 / output.csv!$B34 -> 0.019027 | G40: =output.csv!G34 / output.csv!$B34 -> 0.016865 | H40: =output.csv!H34 / output.csv!$B34 -> 0.018881 | I40: =output.csv!I34 / output.csv!$B34 -> 0.020637 | J40: =output.csv!J34 / output.csv!$B34 -> 0.026227 | ... AR40: =output.csv!AR34 / output.csv!$B34 -> 0.023779
...

Sheet averagelandingpercentage
A1: Average Landing % | B1: Escapes:1000 | C1: Waits:1000 | D1: Escapes:10000 | E1: Waits:10000 | F1: Escapes:100000 | G1: Waits:100000 | H1: Escapes:1000000 | I1: Waits:1000000
A2: {=TRANSPOSE(output.csv!D1:AR1)} -> Jail | B2: {=TRANSPOSE(percentages!$D12:$AR12)} -> 0.0767 | C2: {=TRANSPOSE(percentages!$D60:$AR60)} -> 0.1624 | D2: {=TRANSPOSE(percentages!$D24:$AR24)} -> 0.08135 | E2: {=TRANSPOSE(percentages!$D72:$AR72)} -> 0.15765 | F2: {=TRANSPOSE(percentages!$D36:$AR36)} -> 0.081087 | G2: {=TRANSPOSE(percentages!$D84:$AR84)} -> 0.156712 | H2: {=TRANSPOSE(percentages!$D48:$AR48)} -> 0.0812592 | I2: {=TRANSPOSE(percentages!$D96:$AR96)} -> 0.1574672
A3: Go | B3: 0.0285 | C3: 0.0283 | D3: 0.02858 | E3: 0.02649 | F3: 0.028659 | G3: 0.026383 | H3: 0.0285097 | I3: 0.0261542
A4: Mediterranean Avenue | B4: 0.017 | C4: 0.0169 | D4: 0.01888 | E4: 0.01742 | F4: 0.019165 | G4: 0.01728 | H4: 0.0190117 | I4: 0.0174371
A5: Community Chest1 | B5: 0.0168 | C5: 0.0158 | D5: 0.01727 | E5: 0.01526 | F5: 0.016736 | G5: 0.0154 | H5: 0.016842 | I5: 0.0154175
A6: Baltic Avenue | B6: 0.0225 | C6: 0.0166 | D6: 0.01911 | E6: 0.01764 | F6: 0.019025 | G6: 0.017519 | H6: 0.0190669 | I6: 0.0174935
A7: Income Tax | B7: 0.0211 | C7: 0.0171 | D7: 0.02127 | E7: 0.01882 | F7: 0.020537 | G7: 0.018646 | H7: 0.0204118 | I7: 0.0187314
A8: Reading Railroad | B8: 0.0275 | C8: 0.023 | D8: 0.02613 | E8: 0.02401 | F8: 0.026134 | G8: 0.024174 | H8: 0.0262193 | I8: 0.024164
A9: Oriental Avenue | B9: 0.0202 | C9: 0.0183 | D9: 0.01886 | E9: 0.0174 | F9: 0.019452 | G9: 0.017711 | H9: 0.0196534 | I9: 0.0179883
A10: Chance1 | B10: 0.0085 | C10: 0.0073 | D10: 0.0087 | E10: 0.00842 | F10: 0.00863 | G10: 0.008095 | H10: 0.0086194 | I10: 0.0079138
A11: Vermont Avenue | B11: 0.0184 | C11: 0.0201 | D11: 0.01981 | E11: 0.01786 | F11: 0.019933 | G11: 0.018177 | H11: 0.0197361 | I11: 0.0181555
A12: Connecticut Avenue | B12: 0.0194 | C12: 0.018 | D12: 0.01919 | E12: 0.01776 | F12: 0.019689 | G12: 0.017899 | H12: 0.0195265 | I12: 0.0179166
A13: Just Visiting | B13: 0.0216 | C13: 0.0164 | D13: 0.0191 | E13: 0.01771 | F13: 0.018917 | G13: 0.017427 | H13: 0.0190424 | I13: 0.017525
A14: St. Charles Place | B14: 0.0259 | C14: 0.0197 | D14: 0.02293 | E14: 0.02126 | F14: 0.023053 | G14: 0.021399 | H14: 0.0230722 | I14: 0.0212772
... A42: Boardwalk | B42: 0.0246 | C42: 0.0212 | D42: 0.0239 | E42: 0.02161 | F42: 0.023767 | G42: 0.021957 | H42: 0.0238451 | I42: 0.0219093

Sheet standarddeviationpercentagepoin
A1: Standard Deviation In Percentage Points | B1: Escapes:1000 | C1: Waits:1000 | D1: Escapes:10000 | E1: Waits:10000 | F1: Escapes:100000 | G1: Waits:100000 | H1: Escapes:1000000 | I1: Waits:1000000
A2: {=TRANSPOSE(output.csv!D1:AR1)} -> Jail | B2: {=TRANSPOSE(percentages!$D13:$AR13)} -> 0.39735235 | C2: {=TRANSPOSE(percentages!$D61:$AR61)} -> 1.4848868 | D2: {=TRANSPOSE(percentages!$D25:$AR25)} -> 0.21691012 | E2: {=TRANSPOSE(percentages!$D73:$AR73)} -> 0.42602165 | F2: {=TRANSPOSE(percentages!$D37:$AR37)} -> 0.062418035 | G2: {=TRANSPOSE(percentages!$D85:$AR85)} -> 0.088263243 | H2: {=TRANSPOSE(percentages!$D49:$AR49)} -> 0.018127499 | I2: {=TRANSPOSE(percentages!$D97:$AR97)} -> 0.057471554
A3: Go | B3: 0.64334197 | C3: 0.47387293 | D3: 0.078711851 | E3: 0.12653063 | F3: 0.024632634 | G3: 0.052692082 | H3: 0.011726992 | I3: 0.011230197
A4: Mediterranean Avenue | B4: 0.42687495 | C4: 0.42804465 | D4: 0.17849992 | E4: 0.12752342 | F4: 0.030909366 | G4: 0.033740842 | H4: 0.0099449652 | I4: 0.012088144
A5: Community Chest1 | B5: 0.39665266 | C5: 0.24404007 | D5: 0.092020529 | E5: 0.059104427 | F5: 0.044756626 | G5: 0.033236526 | H5: 0.010280726 | I5: 0.013702899
A6: Baltic Avenue | B6: 0.35355339 | C6: 0.4376706 | D6: 0.13924 | E6: 0.12738393 | F6: 0.047965844 | G6: 0.044660323 | H6: 0.016062064 | I6: 0.013110407
A7: Income Tax | B7: 0.32128215 | C7: 0.33482997 | D7: 0.14659468 | E7: 0.10475368 | F7: 0.033964197 | G7: 0.045753446 | H7: 0.014918877 | I7: 0.013286183
A8: Reading Railroad | B8: 0.38369548 | C8: 0.34960295 | D8: 0.1312377 | E8: 0.083592929 | F8: 0.036533698 | G8: 0.038984897 | H8: 0.010394769 | I8: 0.0073312118
A9: Oriental Avenue | B9: 0.26997942 | C9: 0.33349996 | D9: 0.091796877 | E9: 0.13490738 | F9: 0.019509542 | G9: 0.037017864 | H9: 0.012021388 | I9: 0.0098268397
A10: Chance1 | B10: 0.31358146 | C10: 0.30930029 | D10: 0.098994949 | E10: 0.065962953 | F10: 0.025612497 | G10: 0.029609495 | H10: 0.0071726642 | I10: 0.010605638
A11: Vermont Avenue | B11: 0.31692972 | C11: 0.30349812 | D11: 0.093624546 | E11: 0.16965324 | F11: 0.043550864 | G11: 0.032041813 | H11: 0.015183064 | I11: 0.012534597
A12: Connecticut Avenue | B12: 0.39777157 | C12: 0.22607767 | D12: 0.10332796 | E12: 0.14607456 | F12: 0.040322175 | G12: 0.022263323 | H12: 0.012448137 | I12: 0.017536704
A13: Just Visiting | B13: 0.54812813 | C13: 0.34058773 | D13: 0.13482499 | E13: 0.12160501 | F13: 0.04291089 | G13: 0.043751952 | H13: 0.010955587 | I13: 0.014442145
A14: St. Charles Place | B14: 0.48864893 | C14: 0.54984846 | D14: 0.18672916 | E14: 0.1268595 | F14: 0.046466356 | G14: 0.027977968 | H14: 0.0067281828 | I14: 0.011530134
... A42: Boardwalk | B42: 0.31692972 | C42: 0.48716869 | D42: 0.13080945 | E42: 0.13963842 | F42: 0.037921117 | G42: 0.034593031 | H42: 0.0098063981 | I42: 0.014511455

Sheet averagelandingtable
A1: Tile Number | B1: Tile | C1: Escapes:1000 | D1: Waits:1000 | E1: Escapes:10000 | F1: Waits:10000 | G1: Escapes:100000 | H1: Waits:100000 | I1: Escapes:1000000 | J1: Waits:1000000
A2: 1 | B2: Jail | C2: 0.0767 | D2: 0.1624 | E2: 0.08135 | F2: 0.15765 | G2: 0.081087 | H2: 0.156712 | I2: 0.0812592 | J2: 0.1574672
A3: 2 | B3: Go | C3: 0.0285 | D3: 0.0283 | E3: 0.02858 | F3: 0.02649 | G3: 0.028659 | H3: 0.026383 | I3: 0.0285097 | J3: 0.0261542
A4: 3 | B4: Mediterranean Avenue | C4: 0.017 | D4: 0.0169 | E4: 0.01888 | F4: 0.01742 | G4: 0.019165 | H4: 0.01728 | I4: 0.0190117 | J4: 0.0174371
A5: 4 | B5: Community Chest1 | C5: 0.0168 | D5: 0.0158 | E5: 0.01727 | F5: 0.01526 | G5: 0.016736 | H5: 0.0154 | I5: 0.016842 | J5: 0.0154175
A6: 5 | B6: Baltic Avenue | C6: 0.0225 | D6: 0.0166 | E6: 0.01911 | F6: 0.01764 | G6: 0.019025 | H6: 0.017519 | I6: 0.0190669 | J6: 0.0174935
A7: 6 | B7: Income Tax | C7: 0.0211 | D7: 0.0171 | E7: 0.02127 | F7: 0.01882 | G7: 0.020537 | H7: 0.018646 | I7: 0.0204118 | J7: 0.0187314
A8: 7 | B8: Reading Railroad | C8: 0.0275 | D8: 0.023 | E8: 0.02613 | F8: 0.02401 | G8: 0.026134 | H8: 0.024174 | I8: 0.0262193 | J8: 0.024164
A9: 8 | B9: Oriental Avenue | C9: 0.0202 | D9: 0.0183 | E9: 0.01886 | F9: 0.0174 | G9: 0.019452 | H9: 0.017711 | I9: 0.0196534 | J9: 0.0179883
A10: 9 | B10: Chance1 | C10: 0.0085 | D10: 0.0073 | E10: 0.0087 | F10: 0.00842 | G10: 0.00863 | H10: 0.008095 | I10: 0.0086194 | J10: 0.0079138
A11: 10 | B11: Vermont Avenue | C11: 0.0184 | D11: 0.0201 | E11: 0.01981 | F11: 0.01786 | G11: 0.019933 | H11: 0.018177 | I11: 0.0197361 | J11: 0.0181555
A12: 11 | B12: Connecticut Avenue | C12: 0.0194 | D12: 0.018 | E12: 0.01919 | F12: 0.01776 | G12: 0.019689 | H12: 0.017899 | I12: 0.0195265 | J12: 0.0179166
A13: 12 | B13: Just Visiting | C13: 0.0216 | D13: 0.0164 | E13: 0.0191 | F13: 0.01771 | G13: 0.018917 | H13: 0.017427 | I13: 0.0190424 | J13: 0.017525
... A42: 41 | B42: Boardwalk | C42: 0.0246 | D42: 0.0212 | E42: 0.0239 | F42: 0.02161 | G42: 0.023767 | H42: 0.021957 | I42: 0.0238451 | J42: 0.0219093

Sheet tilerankings
A1: Rank | B1: Escapes:1000 | C1: Waits:1000 | D1: Escapes:10000 | E1: Waits:10000 | F1: Escapes:100000 | G1: Waits:100000 | H1: Escapes:1000000 | I1: Waits:1000000 | K1: Top 5 Appearances | L1: Escapes | M1: Waits
A2: 1 | B2: Jail | C2: Jail | D2: Jail | E2: Jail | F2: Jail | G2: Jail | H2: Jail | I2: Jail | K2: Jail | L2: 4 | M2: 4
A3: 2 | B3: New York Avenue | C3: New York Avenue | D3: New York Avenue | E3: Tennessee Avenue | F3: New York Avenue | G3: Tennessee Avenue | H3: New York Avenue | I3: Tennessee Avenue | K3: New York Avenue | L3: 4 | M3: 3
A4: 3 | B4: Tennessee Avenue | C4: Tennessee Avenue | D4: Illinois Avenue | E4: Illinois Avenue | F4: Tennessee Avenue | G4: Illinois Avenue | H4: Illinois Avenue | I4: Free Parking | K4: Tennessee Avenue | L4: 4 | M4: 4
A5: 4 | B5: B. & O. Railroad | C5: Illinois Avenue | D5: Tennessee Avenue | E5: Free Parking | F5: Illinois Avenue | G5: Free Parking | H5: Tennessee Avenue | I5: Illinois Avenue | K5: B. & O. Railroad | L5: 4 | M5: 0
A6: 5 | B6: St. James Place | C6: Free Parking | D6: B. & O. Railroad | E6: St. James Place | F6: B. & O. Railroad | G6: New York Avenue | H6: B. & O. Railroad | I6: New York Avenue | K6: St. James Place | L6: 1 | M6: 1
A7: 6 | B7: North Carolina Avenue | C7: Go | D7: Free Parking | E7: B. & O. Railroad | F7: Free Parking | G7: B. & O. Railroad | H7: Free Parking | I7: B. & O. Railroad | K7: Illinois Avenue | L7: 3 | M7: 4
A8: 7 | B8: Illinois Avenue | C8: B. & O. Railroad | D8: Kentucky Avenue | E8: New York Avenue | F8: St. James Place | G8: St. James Place | H8: St. James Place | I8: St. James Place | K8: Free Parking | L8: 0 | M8: 4
A9: 8 | B9: Go | C9: St. James Place | D9: Community Chest2 | E9: Kentucky Avenue | F9: Pennsylvania Railroad | G9: Go | H9: Pennsylvania Railroad | I9: Go
A10: 9 | B10: Free Parking | C10: Pennsylvania Railroad | D10: St. James Place | E10: Go | F10: Kentucky Avenue | G10: Kentucky Avenue | H10: Kentucky Avenue | I10: Kentucky Avenue | K10: Top 5 For Large N | L10: Escapes:100000 | M10: Escapes:1000000 | N10: Waits:100000 | O10: Waits:1000000
A11: 10 | B11: Water Works | C11: Virginia Avenue | D11: Pennsylvania Railroad | E11: Water Works | F11: Go | G11: Pennsylvania Railroad | H11: Community Chest2 | I11: Water Works | L11: Jail | M11: Jail | N11: Jail | O11: Jail
A12: 11 | B12: Ventnor Avenue | C12: Water Works | D12: Go | E12: Pennsylvania Railroad | F12: Community Chest2 | G12: Water Works | H12: Go | I12: Pennsylvania Railroad | L12: New York Avenue | M12: New York Avenue | N12: Tennessee Avenue | O12: Tennessee Avenue
A13: 12 | B13: Reading Railroad | C13: Atlantic Avenue | D13: Water Works | E13: Atlantic Avenue | F13: Water Works | G13: Atlantic Avenue | H13: Water Works | I13: Atlantic Avenue | L13: Tennessee Avenue | M13: Illinois Avenue | N13: Illinois Avenue | O13: Free Parking
A14: 13 | B14: Pennsylvania Railroad | C14: Pacific Avenue | D14: Atlantic Avenue | E14: Virginia Avenue | F14: Atlantic Avenue | G14: Reading Railroad | H14: Atlantic Avenue | I14: Indiana Avenue | L14: Illinois Avenue | M14: Tennessee Avenue | N14: Free Parking | O14: Illinois Avenue
A15: 14 | B15: Atlantic Avenue | C15: Indiana Avenue | D15: Indiana Avenue | E15: Indiana Avenue | F15: Indiana Avenue | G15: Community Chest2 | H15: Indiana Avenue | I15: Ventnor Avenue | L15: B. & O. Railroad | M15: B. & O. Railroad | N15: New York Avenue | O15: New York Avenue
A16: 15 | B16: Community Chest2 | C16: Community Chest2 | D16: Reading Railroad | E16: Reading Railroad | F16: Ventnor Avenue | G16: Indiana Avenue | H16: Ventnor Avenue | I16: Reading Railroad
A17: 16 | B17: Virginia Avenue | C17: Electric Company | D17: Ventnor Avenue | E17: Ventnor Avenue | F17: Reading Railroad | G17: Ventnor Avenue | H17: Reading Railroad | I17: Community Chest2 | K17: Escape | L17: Wait
A18: 17 | B18: Indiana Avenue | C18: Marvin Gardens | D18: Pacific Avenue | E18: Community Chest2 | F18: Pacific Avenue | G18: Virginia Avenue | H18: Pacific Avenue | I18: Virginia Avenue | K18: Pennsylvania Railroad | L18: GO
A19: 18 | B19: St. Charles Place | C19: Kentucky Avenue | D19: North Carolina Avenue | E19: North Carolina Avenue | F19: North Carolina Avenue | G19: Electric Company | H19: North Carolina Avenue | I19: Electric Company | K19: Communty Chest2 | L19: Electric Company
A20: 19 | B20: Kentucky Avenue | C20: Ventnor Avenue | D20: Marvin Gardens | E20: Marvin Gardens | F20: Marvin Gardens | G20: Pacific Avenue | H20: Marvin Gardens | I20: Pacific Avenue | K20: New York Avenue | L20: Virginia Avenue
A21: 20 | B21: Pennsylvania Avenue | C21: Reading Railroad | D21: Virginia Avenue | E21: Pacific Avenue | F21: Virginia Avenue | G21: North Carolina Avenue | H21: Virginia Avenue | I21: North Carolina Avenue | K21: B. & O. Railroad | L21: Tennessee Avenue
A22: 21 | B22: Boardwalk | C22: North Carolina Avenue | D22: Boardwalk | E22: Electric Company | F22: Boardwalk | G22: Marvin Gardens | H22: Boardwalk | I22: Marvin Gardens | K22: Pacific Avenue | L22: Free Parking
A23: 22 | B23: Marvin Gardens | C23: Pennsylvania Avenue | D23: Pennsylvania Avenue | E23: Pennsylvania Avenue | F23: Pennsylvania Avenue | G23: Boardwalk | H23: Pennsylvania Avenue | I23: Boardwalk | K23: North Carolina Avenue | L23: Atlantic Avenue
A24: 23 | B24: Short Line | C24: Boardwalk | D24: Electric Company | E24: Boardwalk | F24: Electric Company | G24: Pennsylvania Avenue | H24: Electric Company | I24: Pennsylvania Avenue | K24: Boardwalk | L24: Water Works
A25: 24 | B25: Pacific Avenue | C25: Short Line | D25: St. Charles Place | E25: St. Charles Place | F25: St. Charles Place | G25: St. Charles Place | H25: St. Charles Place | I25: St. Charles Place
A26: 25 | B26: Baltic Avenue | C26: Vermont Avenue | D26: Short Line | E26: Community Chest3 | F26: Community Chest3 | G26: Short Line | H26: Short Line | I26: Short Line
A27: 26 | B27: Electric Company | C27: States Avenue | D27: Community Chest3 | E27: Short Line | F27: Short Line | G27: Community Chest3 | H27: Community Chest3 | I27: Community Chest3 | K27: Tiles Jumped to By Cards | M27: Tiles Near Jail | N27: Parity | O27: Jump | P27: Higher Rank Above n=100,000
A28: 27 | B28: States Avenue | C28: St. Charles Place | D28: States Avenue | E28: States Avenue | F28: States Avenue | G28: States Avenue | H28: States Avenue | I28: States Avenue | K28: Boardwalk | M28: St. Charles Place | N28: Odd | O28: Yes | P28: -
A29: 28 | B29: Just Visiting | C29: Luxury Tax | D29: Income Tax | E29: Income Tax | F29: Income Tax | G29: Income Tax | H29: Income Tax | I29: Income Tax | K29: Go | M29: Electric Company | N29: Even | O29: Yes | P29: B
A30: 29 | B30: Income Tax | C30: Park Place | D30: Luxury Tax | E30: Luxury Tax | F30: Luxury Tax | G30: Luxury Tax | H30: Luxury Tax | I30: Luxury Tax | K30: Illinois Avenue | M30: States Avenue | N30: Odd | P30: -
A31: 30 | B31: Community Chest3 | C31: Community Chest3 | D31: Vermont Avenue | E31: Vermont Avenue | F31: Vermont Avenue | G31: Park Place | H31: Park Place | I31: Vermont Avenue | K31: St. Charles Place | M31: Virginia Avenue | N31: Even | P31: B
A32: 31 | B32: Oriental Avenue | C32: Oriental Avenue | D32: Park Place | E32: Connecticut Avenue | F32: Park Place | G32: Vermont Avenue | H32: Vermont Avenue | I32: Park Place | K32: Reading Railroad | M32: Pennsylvania Railroad | N32: Odd | O32: Yes | P32: A
A33: 32 | B33: Park Place | C33: Connecticut Avenue | D33: Connecticut Avenue | E33: Just Visiting | F33: Connecticut Avenue | G33: Connecticut Avenue | H33: Oriental Avenue | I33: Oriental Avenue | K33: Pennsylvania Railroad | M33: St. James Place | N33: Even | P33: -
A34: 33 | B34: Connecticut Avenue | C34: Income Tax | D34: Baltic Avenue | E34: Baltic Avenue | F34: Oriental Avenue | G34: Oriental Avenue | H34: Connecticut Avenue | I34: Connecticut Avenue | K34: B. &. O. Railroad | M34: Community Chest 2 | N34: Odd | P34: A
A35: 34 | B35: Luxury Tax | C35: Mediterranean Avenue | D35: Just Visiting | E35: Mediterranean Avenue | F35: Mediterranean Avenue | G35: Baltic Avenue | H35: Baltic Avenue | I35: Just Visiting | K35: Electric Company | M35: Tennessee Avenue | N35: Even | P35: B
A36: 35 | B36: Vermont Avenue | C36: Baltic Avenue | D36: Mediterranean Avenue | E36: Oriental Avenue | F36: Baltic Avenue | G36: Just Visiting | H36: Just Visiting | I36: Baltic Avenue | K36: Water Works | M36: New York Avenue | N36: Odd | P36: A
A37: 36 | B37: Mediterranean Avenue | C37: Just Visiting | D37: Oriental Avenue | E37: Park Place | F37: Just Visiting | G37: Mediterranean Avenue | H37: Mediterranean Avenue | I37: Mediterranean Avenue | K37: Income Tax | M37: Free Parking | N37: Even | P37: B
A38: 37 | B38: Community Chest1 | C38: Community Chest1 | D38: Community Chest1 | E38: Community Chest1 | F38: Community Chest1 | G38: Community Chest1 | H38: Community Chest1 | I38: Community Chest1 | K38: New York Avenue | M38: Kentucky Avenue | N38: Odd | P38: -
A39: 38 | B39: Chance2 | C39: Chance2 | D39: Chance2 | E39: Chance2 | F39: Chance2 | G39: Chance2 | H39: Chance2 | I39: Chance2 | K39: Community Chest 3 | M39: Chance2 | N39: Even | P39: -
A40: 39 | B40: Chance3 | C40: Chance3 | D40: Chance3 | E40: Chance1 | F40: Chance3 | G40: Chance3 | H40: Chance3 | I40: Chance3 | K40: Jail | M40: Indiana Avenue | N40: Odd | P40: -
...
